<?xml version="1.0"?>
<robot xmlns:xacro="http://www.ros.org/wiki/xacro">

  <!-- Physical Constants -->
  <xacro:property name="wheel_radius" value="0.09" />
  <xacro:property name="wheel_width" value="0.06" />
  <xacro:property name="wheel_separation" value="0.36" />
  <xacro:property name="base_length" value="0.45" />
  <xacro:property name="base_width" value="0.30" />
  <xacro:property name="base_height" value="0.10" />
  <xacro:property name="pillar_radius" value="0.01" />
  <xacro:property name="pillar_height" value="0.13" />
  <xacro:property name="lidar_length" value="0.096" />
  <xacro:property name="lidar_width" value="0.070" />
  <xacro:property name="lidar_height" value="0.055" />
  <xacro:property name="floor2_thickness" value="0.01" />
  <xacro:property name="floor2_length" value="0.30" />
  <xacro:property name="floor2_width" value="0.20" />

    <!-- 색깔 정의 -->
  <material name="black">
    <color rgba="0.0 0.0 0.0 1.0"/>
  </material>
  <material name="red">
    <color rgba="0.8 0.0 0.0 1.0"/>
  </material>
  <material name="white">
    <color rgba="1.0 1.0 1.0 1.0"/>
  </material>
  <material name="gray">
    <color rgba="0.5 0.5 0.5 1.0"/>
  </material>
  <material name="blue">
    <color rgba="0.0 0.0 0.8 1.0"/>
  </material>

  <!-- Wheel Macro -->
  <xacro:macro name="wheel" params="name x y">
    <link name="${name}">
      <visual>
        <geometry>
          <cylinder radius="${wheel_radius}" length="${wheel_width}" />
        </geometry>
        <material name="black"/>
      </visual>
      <collision>
        <geometry>
          <cylinder radius="${wheel_radius}" length="${wheel_width}" />
        </geometry>
      </collision>
      <inertial>
        <mass value="1.0"/>
        <origin xyz="0 0 0" />
        <inertia ixx="0.001" ixy="0.0" ixz="0.0" iyy="0.001" iyz="0.0" izz="0.001" />
      </inertial>
    </link>
    <joint name="${name}_joint" type="continuous">
      <parent link="base_frame"/>
      <child link="${name}"/>
      <origin xyz="${x} ${y} ${wheel_radius}" rpy="0 0 0" />
      <axis xyz="0 1 0" />
    </joint>
  </xacro:macro>

  <!-- Pillar Macro -->
  <xacro:macro name="pillar" params="name x y">
    <link name="${name}">
      <visual>
        <geometry>
          <cylinder radius="${pillar_radius}" length="${pillar_height}" />
        </geometry>
        <material name="gray"/>
      </visual>
      <collision>
        <geometry>
          <cylinder radius="${pillar_radius}" length="${pillar_height}" />
        </geometry>
      </collision>
    </link>
    <joint name="${name}_joint" type="fixed">
      <parent link="base_frame"/>
      <child link="${name}"/>
      <origin xyz="${x} ${y} ${base_height}" rpy="0 0 0" />
    </joint>
  </xacro:macro>

</robot>
